2024-02-09 23:28:03.661 Uncaught app exception

Traceback (most recent call last):

  File "/home/adminuser/venv/lib/python3.9/site-packages/streamlit/runtime/scriptrunner/script_runner.py", line 535, in _run_script

    exec(code, module.__dict__)

  File "/mount/src/apl_aws/streamlit_app.py", line 17, in <module>

    obj = s3.get_object(Bucket=bucket_name, Key=object_key)

  File "/home/adminuser/venv/lib/python3.9/site-packages/botocore/client.py", line 553, in _api_call

    return self._make_api_call(operation_name, kwargs)

  File "/home/adminuser/venv/lib/python3.9/site-packages/botocore/client.py", line 989, in _make_api_call

    http, parsed_response = self._make_request(

  File "/home/adminuser/venv/lib/python3.9/site-packages/botocore/client.py", line 1015, in _make_request

    return self._endpoint.make_request(operation_model, request_dict)

  File "/home/adminuser/venv/lib/python3.9/site-packages/botocore/endpoint.py", line 119, in make_request

    return self._send_request(request_dict, operation_model)

  File "/home/adminuser/venv/lib/python3.9/site-packages/botocore/endpoint.py", line 198, in _send_request

    request = self.create_request(request_dict, operation_model)

  File "/home/adminuser/venv/lib/python3.9/site-packages/botocore/endpoint.py", line 134, in create_request

    self._event_emitter.emit(

  File "/home/adminuser/venv/lib/python3.9/site-packages/botocore/hooks.py", line 412, in emit

    return self._emitter.emit(aliased_event_name, **kwargs)

  File "/home/adminuser/venv/lib/python3.9/site-packages/botocore/hooks.py", line 256, in emit

    return self._emit(event_name, kwargs)

  File "/home/adminuser/venv/lib/python3.9/site-packages/botocore/hooks.py", line 239, in _emit

    response = handler(**kwargs)

  File "/home/adminuser/venv/lib/python3.9/site-packages/botocore/signers.py", line 105, in handler

    return self.sign(operation_name, request)

  File "/home/adminuser/venv/lib/python3.9/site-packages/botocore/signers.py", line 195, in sign

    auth.add_auth(request)

  File "/home/adminuser/venv/lib/python3.9/site-packages/botocore/auth.py", line 418, in add_auth

    raise NoCredentialsError()

botocore.exceptions.NoCredentialsError: Unable to locate credentials

[23:28:03] ❗️

2024-02-09 23:28:03.733 503 GET /script-health-check (10.12.24.117) 914.37ms

2024-02-09 23:28:07.968 Uncaught app exception

Traceback (most recent call last):

  File "/home/adminuser/venv/lib/python3.9/site-packages/streamlit/runtime/scriptrunner/script_runner.py", line 535, in _run_script

    exec(code, module.__dict__)

  File "/mount/src/apl_aws/streamlit_app.py", line 17, in <module>

    obj = s3.get_object(Bucket=bucket_name, Key=object_key)

  File "/home/adminuser/venv/lib/python3.9/site-packages/botocore/client.py", line 553, in _api_call

    return self._make_api_call(operation_name, kwargs)

  File "/home/adminuser/venv/lib/python3.9/site-packages/botocore/client.py", line 989, in _make_api_call

    http, parsed_response = self._make_request(

  File "/home/adminuser/venv/lib/python3.9/site-packages/botocore/client.py", line 1015, in _make_request

    return self._endpoint.make_request(operation_model, request_dict)

  File "/home/adminuser/venv/lib/python3.9/site-packages/botocore/endpoint.py", line 119, in make_request

    return self._send_request(request_dict, operation_model)

  File "/home/adminuser/venv/lib/python3.9/site-packages/botocore/endpoint.py", line 198, in _send_request

    request = self.create_request(request_dict, operation_model)

  File "/home/adminuser/venv/lib/python3.9/site-packages/botocore/endpoint.py", line 134, in create_request

    self._event_emitter.emit(

  File "/home/adminuser/venv/lib/python3.9/site-packages/botocore/hooks.py", line 412, in emit

    return self._emitter.emit(aliased_event_name, **kwargs)

  File "/home/adminuser/venv/lib/python3.9/site-packages/botocore/hooks.py", line 256, in emit

    return self._emit(event_name, kwargs)

  File "/home/adminuser/venv/lib/python3.9/site-packages/botocore/hooks.py", line 239, in _emit

    response = handler(**kwargs)

  File "/home/adminuser/venv/lib/python3.9/site-packages/botocore/signers.py", line 105, in handler

    return self.sign(operation_name, request)

  File "/home/adminuser/venv/lib/python3.9/site-packages/botocore/signers.py", line 195, in sign

    auth.add_auth(request)

  File "/home/adminuser/venv/lib/python3.9/site-packages/botocore/auth.py", line 418, in add_auth

    raise NoCredentialsError()

botocore.exceptions.NoCredentialsError: Unable to locate credentials

2024-02-09 23:28:08.150 503 GET /script-health-check (10.12.24.117) 195.20ms

2024-02-09 23:28:12.895 Uncaught app exception

Traceback (most recent call last):

  File "/home/adminuser/venv/lib/python3.9/site-packages/streamlit/runtime/scriptrunner/script_runner.py", line 535, in _run_script

    exec(code, module.__dict__)

  File "/mount/src/apl_aws/streamlit_app.py", line 17, in <module>

    obj = s3.get_object(Bucket=bucket_name, Key=object_key)

  File "/home/adminuser/venv/lib/python3.9/site-packages/botocore/client.py", line 553, in _api_call

    return self._make_api_call(operation_name, kwargs)

  File "/home/adminuser/venv/lib/python3.9/site-packages/botocore/client.py", line 989, in _make_api_call

    http, parsed_response = self._make_request(

  File "/home/adminuser/venv/lib/python3.9/site-packages/botocore/client.py", line 1015, in _make_request

    return self._endpoint.make_request(operation_model, request_dict)

  File "/home/adminuser/venv/lib/python3.9/site-packages/botocore/endpoint.py", line 119, in make_request

    return self._send_request(request_dict, operation_model)

  File "/home/adminuser/venv/lib/python3.9/site-packages/botocore/endpoint.py", line 198, in _send_request

    request = self.create_request(request_dict, operation_model)

  File "/home/adminuser/venv/lib/python3.9/site-packages/botocore/endpoint.py", line 134, in create_request

    self._event_emitter.emit(

  File "/home/adminuser/venv/lib/python3.9/site-packages/botocore/hooks.py", line 412, in emit

    return self._emitter.emit(aliased_event_name, **kwargs)

  File "/home/adminuser/venv/lib/python3.9/site-packages/botocore/hooks.py", line 256, in emit

    return self._emit(event_name, kwargs)

  File "/home/adminuser/venv/lib/python3.9/site-packages/botocore/hooks.py", line 239, in _emit

    response = handler(**kwargs)

  File "/home/adminuser/venv/lib/python3.9/site-packages/botocore/signers.py", line 105, in handler

    return self.sign(operation_name, request)

  File "/home/adminuser/venv/lib/python3.9/site-packages/botocore/signers.py", line 195, in sign

    auth.add_auth(request)

  File "/home/adminuser/venv/lib/python3.9/site-packages/botocore/auth.py", line 418, in add_auth

    raise NoCredentialsError()

botocore.exceptions.NoCredentialsError: Unable to locate credentials

2024-02-09 23:28:13.159 503 GET /script-health-check (10.12.24.117) 313.98ms

2024-02-09 23:28:17.048 Uncaught app exception

Traceback (most recent call last):

  File "/home/adminuser/venv/lib/python3.9/site-packages/streamlit/runtime/scriptrunner/script_runner.py", line 535, in _run_script

    exec(code, module.__dict__)

  File "/mount/src/apl_aws/streamlit_app.py", line 17, in <module>

    obj = s3.get_object(Bucket=bucket_name, Key=object_key)

  File "/home/adminuser/venv/lib/python3.9/site-packages/botocore/client.py", line 553, in _api_call

    return self._make_api_call(operation_name, kwargs)

  File "/home/adminuser/venv/lib/python3.9/site-packages/botocore/client.py", line 989, in _make_api_call

    http, parsed_response = self._make_request(

  File "/home/adminuser/venv/lib/python3.9/site-packages/botocore/client.py", line 1015, in _make_request

    return self._endpoint.make_request(operation_model, request_dict)

  File "/home/adminuser/venv/lib/python3.9/site-packages/botocore/endpoint.py", line 119, in make_request

    return self._send_request(request_dict, operation_model)

  File "/home/adminuser/venv/lib/python3.9/site-packages/botocore/endpoint.py", line 198, in _send_request

    request = self.create_request(request_dict, operation_model)

  File "/home/adminuser/venv/lib/python3.9/site-packages/botocore/endpoint.py", line 134, in create_request

    self._event_emitter.emit(

  File "/home/adminuser/venv/lib/python3.9/site-packages/botocore/hooks.py", line 412, in emit

    return self._emitter.emit(aliased_event_name, **kwargs)

  File "/home/adminuser/venv/lib/python3.9/site-packages/botocore/hooks.py", line 256, in emit

    return self._emit(event_name, kwargs)

  File "/home/adminuser/venv/lib/python3.9/site-packages/botocore/hooks.py", line 239, in _emit

    response = handler(**kwargs)

  File "/home/adminuser/venv/lib/python3.9/site-packages/botocore/signers.py", line 105, in handler

    return self.sign(operation_name, request)

  File "/home/adminuser/venv/lib/python3.9/site-packages/botocore/signers.py", line 195, in sign

    auth.add_auth(request)

  File "/home/adminuser/venv/lib/python3.9/site-packages/botocore/auth.py", line 418, in add_auth

    raise NoCredentialsError()

botocore.exceptions.NoCredentialsError: Unable to locate credentials

2024-02-09 23:28:18.056 Uncaught app exception

Traceback (most recent call last):

  File "/home/adminuser/venv/lib/python3.9/site-packages/streamlit/runtime/scriptrunner/script_runner.py", line 535, in _run_script

    exec(code, module.__dict__)

  File "/mount/src/apl_aws/streamlit_app.py", line 17, in <module>

    obj = s3.get_object(Bucket=bucket_name, Key=object_key)

  File "/home/adminuser/venv/lib/python3.9/site-packages/botocore/client.py", line 553, in _api_call

    return self._make_api_call(operation_name, kwargs)

  File "/home/adminuser/venv/lib/python3.9/site-packages/botocore/client.py", line 989, in _make_api_call

    http, parsed_response = self._make_request(

  File "/home/adminuser/venv/lib/python3.9/site-packages/botocore/client.py", line 1015, in _make_request

    return self._endpoint.make_request(operation_model, request_dict)

  File "/home/adminuser/venv/lib/python3.9/site-packages/botocore/endpoint.py", line 119, in make_request

    return self._send_request(request_dict, operation_model)

  File "/home/adminuser/venv/lib/python3.9/site-packages/botocore/endpoint.py", line 198, in _send_request

    request = self.create_request(request_dict, operation_model)

  File "/home/adminuser/venv/lib/python3.9/site-packages/botocore/endpoint.py", line 134, in create_request

    self._event_emitter.emit(

  File "/home/adminuser/venv/lib/python3.9/site-packages/botocore/hooks.py", line 412, in emit

    return self._emitter.emit(aliased_event_name, **kwargs)

  File "/home/adminuser/venv/lib/python3.9/site-packages/botocore/hooks.py", line 256, in emit

    return self._emit(event_name, kwargs)

  File "/home/adminuser/venv/lib/python3.9/site-packages/botocore/hooks.py", line 239, in _emit

    response = handler(**kwargs)

  File "/home/adminuser/venv/lib/python3.9/site-packages/botocore/signers.py", line 105, in handler

    return self.sign(operation_name, request)

  File "/home/adminuser/venv/lib/python3.9/site-packages/botocore/signers.py", line 195, in sign

    auth.add_auth(request)

  File "/home/adminuser/venv/lib/python3.9/site-packages/botocore/auth.py", line 418, in add_auth

    raise NoCredentialsError()

botocore.exceptions.NoCredentialsError: Unable to locate credentials

2024-02-09 23:28:18.263 503 GET /script-health-check (10.12.24.117) 224.04ms

2024-02-09 23:28:22.958 Uncaught app exception

Traceback (most recent call last):

  File "/home/adminuser/venv/lib/python3.9/site-packages/streamlit/runtime/scriptrunner/script_runner.py", line 535, in _run_script

    exec(code, module.__dict__)

  File "/mount/src/apl_aws/streamlit_app.py", line 17, in <module>

    obj = s3.get_object(Bucket=bucket_name, Key=object_key)

  File "/home/adminuser/venv/lib/python3.9/site-packages/botocore/client.py", line 553, in _api_call

    return self._make_api_call(operation_name, kwargs)

  File "/home/adminuser/venv/lib/python3.9/site-packages/botocore/client.py", line 989, in _make_api_call

    http, parsed_response = self._make_request(

  File "/home/adminuser/venv/lib/python3.9/site-packages/botocore/client.py", line 1015, in _make_request

    return self._endpoint.make_request(operation_model, request_dict)

  File "/home/adminuser/venv/lib/python3.9/site-packages/botocore/endpoint.py", line 119, in make_request

    return self._send_request(request_dict, operation_model)

  File "/home/adminuser/venv/lib/python3.9/site-packages/botocore/endpoint.py", line 198, in _send_request

    request = self.create_request(request_dict, operation_model)

  File "/home/adminuser/venv/lib/python3.9/site-packages/botocore/endpoint.py", line 134, in create_request

    self._event_emitter.emit(

  File "/home/adminuser/venv/lib/python3.9/site-packages/botocore/hooks.py", line 412, in emit

    return self._emitter.emit(aliased_event_name, **kwargs)

  File "/home/adminuser/venv/lib/python3.9/site-packages/botocore/hooks.py", line 256, in emit

    return self._emit(event_name, kwargs)

  File "/home/adminuser/venv/lib/python3.9/site-packages/botocore/hooks.py", line 239, in _emit

    response = handler(**kwargs)

  File "/home/adminuser/venv/lib/python3.9/site-packages/botocore/signers.py", line 105, in handler

    return self.sign(operation_name, request)

  File "/home/adminuser/venv/lib/python3.9/site-packages/botocore/signers.py", line 195, in sign

    auth.add_auth(request)

  File "/home/adminuser/venv/lib/python3.9/site-packages/botocore/auth.py", line 418, in add_auth

    raise NoCredentialsError()

botocore.exceptions.NoCredentialsError: Unable to locate credentials

2024-02-09 23:28:23.200 503 GET /script-health-check (10.12.24.117) 261.17ms

2024-02-09 23:28:27.796 Uncaught app exception

Traceback (most recent call last):

  File "/home/adminuser/venv/lib/python3.9/site-packages/streamlit/runtime/scriptrunner/script_runner.py", line 535, in _run_script

    exec(code, module.__dict__)

  File "/mount/src/apl_aws/streamlit_app.py", line 17, in <module>

    obj = s3.get_object(Bucket=bucket_name, Key=object_key)

  File "/home/adminuser/venv/lib/python3.9/site-packages/botocore/client.py", line 553, in _api_call

    return self._make_api_call(operation_name, kwargs)

  File "/home/adminuser/venv/lib/python3.9/site-packages/botocore/client.py", line 989, in _make_api_call

    http, parsed_response = self._make_request(

  File "/home/adminuser/venv/lib/python3.9/site-packages/botocore/client.py", line 1015, in _make_request

    return self._endpoint.make_request(operation_model, request_dict)

  File "/home/adminuser/venv/lib/python3.9/site-packages/botocore/endpoint.py", line 119, in make_request

    return self._send_request(request_dict, operation_model)

  File "/home/adminuser/venv/lib/python3.9/site-packages/botocore/endpoint.py", line 198, in _send_request

    request = self.create_request(request_dict, operation_model)

  File "/home/adminuser/venv/lib/python3.9/site-packages/botocore/endpoint.py", line 134, in create_request

    self._event_emitter.emit(

  File "/home/adminuser/venv/lib/python3.9/site-packages/botocore/hooks.py", line 412, in emit

    return self._emitter.emit(aliased_event_name, **kwargs)

  File "/home/adminuser/venv/lib/python3.9/site-packages/botocore/hooks.py", line 256, in emit

    return self._emit(event_name, kwargs)

  File "/home/adminuser/venv/lib/python3.9/site-packages/botocore/hooks.py", line 239, in _emit

    response = handler(**kwargs)

  File "/home/adminuser/venv/lib/python3.9/site-packages/botocore/signers.py", line 105, in handler

    return self.sign(operation_name, request)

  File "/home/adminuser/venv/lib/python3.9/site-packages/botocore/signers.py", line 195, in sign

    auth.add_auth(request)

  File "/home/adminuser/venv/lib/python3.9/site-packages/botocore/auth.py", line 418, in add_auth

    raise NoCredentialsError()

botocore.exceptions.NoCredentialsError: Unable to locate credentials

2024-02-09 23:28:28.049 503 GET /script-health-check (10.12.24.117) 270.32ms

2024-02-09 23:28:32.829 Uncaught app exception

Traceback (most recent call last):

  File "/home/adminuser/venv/lib/python3.9/site-packages/streamlit/runtime/scriptrunner/script_runner.py", line 535, in _run_script

    exec(code, module.__dict__)

  File "/mount/src/apl_aws/streamlit_app.py", line 17, in <module>

    obj = s3.get_object(Bucket=bucket_name, Key=object_key)

  File "/home/adminuser/venv/lib/python3.9/site-packages/botocore/client.py", line 553, in _api_call

    return self._make_api_call(operation_name, kwargs)

  File "/home/adminuser/venv/lib/python3.9/site-packages/botocore/client.py", line 989, in _make_api_call

    http, parsed_response = self._make_request(

  File "/home/adminuser/venv/lib/python3.9/site-packages/botocore/client.py", line 1015, in _make_request

    return self._endpoint.make_request(operation_model, request_dict)

  File "/home/adminuser/venv/lib/python3.9/site-packages/botocore/endpoint.py", line 119, in make_request

    return self._send_request(request_dict, operation_model)

  File "/home/adminuser/venv/lib/python3.9/site-packages/botocore/endpoint.py", line 198, in _send_request

    request = self.create_request(request_dict, operation_model)

  File "/home/adminuser/venv/lib/python3.9/site-packages/botocore/endpoint.py", line 134, in create_request

    self._event_emitter.emit(

  File "/home/adminuser/venv/lib/python3.9/site-packages/botocore/hooks.py", line 412, in emit

    return self._emitter.emit(aliased_event_name, **kwargs)

  File "/home/adminuser/venv/lib/python3.9/site-packages/botocore/hooks.py", line 256, in emit

    return self._emit(event_name, kwargs)

  File "/home/adminuser/venv/lib/python3.9/site-packages/botocore/hooks.py", line 239, in _emit

    response = handler(**kwargs)

  File "/home/adminuser/venv/lib/python3.9/site-packages/botocore/signers.py", line 105, in handler

    return self.sign(operation_name, request)

  File "/home/adminuser/venv/lib/python3.9/site-packages/botocore/signers.py", line 195, in sign

    auth.add_auth(request)

  File "/home/adminuser/venv/lib/python3.9/site-packages/botocore/auth.py", line 418, in add_auth

    raise NoCredentialsError()

botocore.exceptions.NoCredentialsError: Unable to locate credentials

2024-02-09 23:28:33.117 503 GET /script-health-check (10.12.24.117) 311.03ms

2024-02-09 23:28:37.847 Uncaught app exception

Traceback (most recent call last):

  File "/home/adminuser/venv/lib/python3.9/site-packages/streamlit/runtime/scriptrunner/script_runner.py", line 535, in _run_script

    exec(code, module.__dict__)

  File "/mount/src/apl_aws/streamlit_app.py", line 17, in <module>

    obj = s3.get_object(Bucket=bucket_name, Key=object_key)

  File "/home/adminuser/venv/lib/python3.9/site-packages/botocore/client.py", line 553, in _api_call

    return self._make_api_call(operation_name, kwargs)

  File "/home/adminuser/venv/lib/python3.9/site-packages/botocore/client.py", line 989, in _make_api_call

    http, parsed_response = self._make_request(

  File "/home/adminuser/venv/lib/python3.9/site-packages/botocore/client.py", line 1015, in _make_request

    return self._endpoint.make_request(operation_model, request_dict)

  File "/home/adminuser/venv/lib/python3.9/site-packages/botocore/endpoint.py", line 119, in make_request

    return self._send_request(request_dict, operation_model)

  File "/home/adminuser/venv/lib/python3.9/site-packages/botocore/endpoint.py", line 198, in _send_request

    request = self.create_request(request_dict, operation_model)

  File "/home/adminuser/venv/lib/python3.9/site-packages/botocore/endpoint.py", line 134, in create_request

    self._event_emitter.emit(

  File "/home/adminuser/venv/lib/python3.9/site-packages/botocore/hooks.py", line 412, in emit

    return self._emitter.emit(aliased_event_name, **kwargs)

  File "/home/adminuser/venv/lib/python3.9/site-packages/botocore/hooks.py", line 256, in emit

    return self._emit(event_name, kwargs)

  File "/home/adminuser/venv/lib/python3.9/site-packages/botocore/hooks.py", line 239, in _emit

    response = handler(**kwargs)

  File "/home/adminuser/venv/lib/python3.9/site-packages/botocore/signers.py", line 105, in handler

    return self.sign(operation_name, request)

  File "/home/adminuser/venv/lib/python3.9/site-packages/botocore/signers.py", line 195, in sign

    auth.add_auth(request)

  File "/home/adminuser/venv/lib/python3.9/site-packages/botocore/auth.py", line 418, in add_auth

    raise NoCredentialsError()

botocore.exceptions.NoCredentialsError: Unable to locate credentials

2024-02-09 23:28:38.103 503 GET /script-health-check (10.12.24.117) 314.34ms

2024-02-09 23:28:43.005 Uncaught app exception

Traceback (most recent call last):

  File "/home/adminuser/venv/lib/python3.9/site-packages/streamlit/runtime/scriptrunner/script_runner.py", line 535, in _run_script

    exec(code, module.__dict__)

  File "/mount/src/apl_aws/streamlit_app.py", line 17, in <module>

    obj = s3.get_object(Bucket=bucket_name, Key=object_key)

  File "/home/adminuser/venv/lib/python3.9/site-packages/botocore/client.py", line 553, in _api_call

    return self._make_api_call(operation_name, kwargs)

  File "/home/adminuser/venv/lib/python3.9/site-packages/botocore/client.py", line 989, in _make_api_call

    http, parsed_response = self._make_request(

  File "/home/adminuser/venv/lib/python3.9/site-packages/botocore/client.py", line 1015, in _make_request

    return self._endpoint.make_request(operation_model, request_dict)

  File "/home/adminuser/venv/lib/python3.9/site-packages/botocore/endpoint.py", line 119, in make_request

    return self._send_request(request_dict, operation_model)

  File "/home/adminuser/venv/lib/python3.9/site-packages/botocore/endpoint.py", line 198, in _send_request

    request = self.create_request(request_dict, operation_model)

  File "/home/adminuser/venv/lib/python3.9/site-packages/botocore/endpoint.py", line 134, in create_request

    self._event_emitter.emit(

  File "/home/adminuser/venv/lib/python3.9/site-packages/botocore/hooks.py", line 412, in emit

    return self._emitter.emit(aliased_event_name, **kwargs)

  File "/home/adminuser/venv/lib/python3.9/site-packages/botocore/hooks.py", line 256, in emit

    return self._emit(event_name, kwargs)

  File "/home/adminuser/venv/lib/python3.9/site-packages/botocore/hooks.py", line 239, in _emit

    response = handler(**kwargs)

  File "/home/adminuser/venv/lib/python3.9/site-packages/botocore/signers.py", line 105, in handler

    return self.sign(operation_name, request)

  File "/home/adminuser/venv/lib/python3.9/site-packages/botocore/signers.py", line 195, in sign

    auth.add_auth(request)

  File "/home/adminuser/venv/lib/python3.9/site-packages/botocore/auth.py", line 418, in add_auth

    raise NoCredentialsError()

botocore.exceptions.NoCredentialsError: Unable to locate credentials

2024-02-09 23:28:43.236 503 GET /script-health-check (10.12.24.117) 249.54ms

2024-02-09 23:28:47.916 Uncaught app exception

Traceback (most recent call last):

  File "/home/adminuser/venv/lib/python3.9/site-packages/streamlit/runtime/scriptrunner/script_runner.py", line 535, in _run_script

    exec(code, module.__dict__)

  File "/mount/src/apl_aws/streamlit_app.py", line 17, in <module>

    obj = s3.get_object(Bucket=bucket_name, Key=object_key)

  File "/home/adminuser/venv/lib/python3.9/site-packages/botocore/client.py", line 553, in _api_call

    return self._make_api_call(operation_name, kwargs)

  File "/home/adminuser/venv/lib/python3.9/site-packages/botocore/client.py", line 989, in _make_api_call

    http, parsed_response = self._make_request(

  File "/home/adminuser/venv/lib/python3.9/site-packages/botocore/client.py", line 1015, in _make_request

    return self._endpoint.make_request(operation_model, request_dict)

  File "/home/adminuser/venv/lib/python3.9/site-packages/botocore/endpoint.py", line 119, in make_request

    return self._send_request(request_dict, operation_model)

  File "/home/adminuser/venv/lib/python3.9/site-packages/botocore/endpoint.py", line 198, in _send_request

    request = self.create_request(request_dict, operation_model)

  File "/home/adminuser/venv/lib/python3.9/site-packages/botocore/endpoint.py", line 134, in create_request

    self._event_emitter.emit(

  File "/home/adminuser/venv/lib/python3.9/site-packages/botocore/hooks.py", line 412, in emit

    return self._emitter.emit(aliased_event_name, **kwargs)

  File "/home/adminuser/venv/lib/python3.9/site-packages/botocore/hooks.py", line 256, in emit

    return self._emit(event_name, kwargs)

  File "/home/adminuser/venv/lib/python3.9/site-packages/botocore/hooks.py", line 239, in _emit

    response = handler(**kwargs)

  File "/home/adminuser/venv/lib/python3.9/site-packages/botocore/signers.py", line 105, in handler

    return self.sign(operation_name, request)

  File "/home/adminuser/venv/lib/python3.9/site-packages/botocore/signers.py", line 195, in sign

    auth.add_auth(request)

  File "/home/adminuser/venv/lib/python3.9/site-packages/botocore/auth.py", line 418, in add_auth

    raise NoCredentialsError()

botocore.exceptions.NoCredentialsError: Unable to locate credentials

2024-02-09 23:28:48.176 503 GET /script-health-check (10.12.24.117) 297.04ms

2024-02-09 23:28:52.796 Uncaught app exception

Traceback (most recent call last):

  File "/home/adminuser/venv/lib/python3.9/site-packages/streamlit/runtime/scriptrunner/script_runner.py", line 535, in _run_script

    exec(code, module.__dict__)

  File "/mount/src/apl_aws/streamlit_app.py", line 17, in <module>

    obj = s3.get_object(Bucket=bucket_name, Key=object_key)

  File "/home/adminuser/venv/lib/python3.9/site-packages/botocore/client.py", line 553, in _api_call

    return self._make_api_call(operation_name, kwargs)

  File "/home/adminuser/venv/lib/python3.9/site-packages/botocore/client.py", line 989, in _make_api_call

    http, parsed_response = self._make_request(

  File "/home/adminuser/venv/lib/python3.9/site-packages/botocore/client.py", line 1015, in _make_request

    return self._endpoint.make_request(operation_model, request_dict)

  File "/home/adminuser/venv/lib/python3.9/site-packages/botocore/endpoint.py", line 119, in make_request

    return self._send_request(request_dict, operation_model)

  File "/home/adminuser/venv/lib/python3.9/site-packages/botocore/endpoint.py", line 198, in _send_request

    request = self.create_request(request_dict, operation_model)

  File "/home/adminuser/venv/lib/python3.9/site-packages/botocore/endpoint.py", line 134, in create_request

    self._event_emitter.emit(

  File "/home/adminuser/venv/lib/python3.9/site-packages/botocore/hooks.py", line 412, in emit

    return self._emitter.emit(aliased_event_name, **kwargs)

  File "/home/adminuser/venv/lib/python3.9/site-packages/botocore/hooks.py", line 256, in emit

    return self._emit(event_name, kwargs)

  File "/home/adminuser/venv/lib/python3.9/site-packages/botocore/hooks.py", line 239, in _emit

    response = handler(**kwargs)

  File "/home/adminuser/venv/lib/python3.9/site-packages/botocore/signers.py", line 105, in handler

    return self.sign(operation_name, request)

  File "/home/adminuser/venv/lib/python3.9/site-packages/botocore/signers.py", line 195, in sign

    auth.add_auth(request)

  File "/home/adminuser/venv/lib/python3.9/site-packages/botocore/auth.py", line 418, in add_auth

    raise NoCredentialsError()

botocore.exceptions.NoCredentialsError: Unable to locate credentials

2024-02-09 23:28:53.069 503 GET /script-health-check (10.12.24.117) 307.92ms

2024-02-09 23:28:57.961 Uncaught app exception

Traceback (most recent call last):

  File "/home/adminuser/venv/lib/python3.9/site-packages/streamlit/runtime/scriptrunner/script_runner.py", line 535, in _run_script

    exec(code, module.__dict__)

  File "/mount/src/apl_aws/streamlit_app.py", line 17, in <module>

    obj = s3.get_object(Bucket=bucket_name, Key=object_key)

  File "/home/adminuser/venv/lib/python3.9/site-packages/botocore/client.py", line 553, in _api_call

    return self._make_api_call(operation_name, kwargs)

  File "/home/adminuser/venv/lib/python3.9/site-packages/botocore/client.py", line 989, in _make_api_call

    http, parsed_response = self._make_request(

  File "/home/adminuser/venv/lib/python3.9/site-packages/botocore/client.py", line 1015, in _make_request

    return self._endpoint.make_request(operation_model, request_dict)

  File "/home/adminuser/venv/lib/python3.9/site-packages/botocore/endpoint.py", line 119, in make_request

    return self._send_request(request_dict, operation_model)

  File "/home/adminuser/venv/lib/python3.9/site-packages/botocore/endpoint.py", line 198, in _send_request

    request = self.create_request(request_dict, operation_model)

  File "/home/adminuser/venv/lib/python3.9/site-packages/botocore/endpoint.py", line 134, in create_request

    self._event_emitter.emit(

  File "/home/adminuser/venv/lib/python3.9/site-packages/botocore/hooks.py", line 412, in emit

    return self._emitter.emit(aliased_event_name, **kwargs)

  File "/home/adminuser/venv/lib/python3.9/site-packages/botocore/hooks.py", line 256, in emit

    return self._emit(event_name, kwargs)

  File "/home/adminuser/venv/lib/python3.9/site-packages/botocore/hooks.py", line 239, in _emit

    response = handler(**kwargs)

  File "/home/adminuser/venv/lib/python3.9/site-packages/botocore/signers.py", line 105, in handler

    return self.sign(operation_name, request)

  File "/home/adminuser/venv/lib/python3.9/site-packages/botocore/signers.py", line 195, in sign

    auth.add_auth(request)

  File "/home/adminuser/venv/lib/python3.9/site-packages/botocore/auth.py", line 418, in add_auth

    raise NoCredentialsError()

botocore.exceptions.NoCredentialsError: Unable to locate credentials

2024-02-09 23:28:58.165 503 GET /script-health-check (10.12.24.117) 225.98ms

2024-02-09 23:29:02.923 Uncaught app exception

Traceback (most recent call last):

  File "/home/adminuser/venv/lib/python3.9/site-packages/streamlit/runtime/scriptrunner/script_runner.py", line 535, in _run_script

    exec(code, module.__dict__)

  File "/mount/src/apl_aws/streamlit_app.py", line 17, in <module>

    obj = s3.get_object(Bucket=bucket_name, Key=object_key)

  File "/home/adminuser/venv/lib/python3.9/site-packages/botocore/client.py", line 553, in _api_call

    return self._make_api_call(operation_name, kwargs)

  File "/home/adminuser/venv/lib/python3.9/site-packages/botocore/client.py", line 989, in _make_api_call

    http, parsed_response = self._make_request(

  File "/home/adminuser/venv/lib/python3.9/site-packages/botocore/client.py", line 1015, in _make_request

    return self._endpoint.make_request(operation_model, request_dict)

  File "/home/adminuser/venv/lib/python3.9/site-packages/botocore/endpoint.py", line 119, in make_request

    return self._send_request(request_dict, operation_model)

  File "/home/adminuser/venv/lib/python3.9/site-packages/botocore/endpoint.py", line 198, in _send_request

    request = self.create_request(request_dict, operation_model)

  File "/home/adminuser/venv/lib/python3.9/site-packages/botocore/endpoint.py", line 134, in create_request

    self._event_emitter.emit(

  File "/home/adminuser/venv/lib/python3.9/site-packages/botocore/hooks.py", line 412, in emit

    return self._emitter.emit(aliased_event_name, **kwargs)

  File "/home/adminuser/venv/lib/python3.9/site-packages/botocore/hooks.py", line 256, in emit

    return self._emit(event_name, kwargs)

  File "/home/adminuser/venv/lib/python3.9/site-packages/botocore/hooks.py", line 239, in _emit

    response = handler(**kwargs)

  File "/home/adminuser/venv/lib/python3.9/site-packages/botocore/signers.py", line 105, in handler

    return self.sign(operation_name, request)

  File "/home/adminuser/venv/lib/python3.9/site-packages/botocore/signers.py", line 195, in sign

    auth.add_auth(request)

  File "/home/adminuser/venv/lib/python3.9/site-packages/botocore/auth.py", line 418, in add_auth

    raise NoCredentialsError()

botocore.exceptions.NoCredentialsError: Unable to locate credentials

2024-02-09 23:29:03.121 503 GET /script-health-check (10.12.24.117) 240.88ms